<?xml version='1.0'?>
<robot name="hamer_mini">

	<link name="dummy">
	<!-- Dummy Link -->
   	</link>
	<!-- Dummy Joint -->
  	<joint name="dummy_joint" type="fixed">
     		<parent link="dummy"/>
     		<child link="base_link"/>
   	</joint>

	<!-- Base Link -->
	<link name="base_link">
	 	<visual>
		   <origin xyz="0 0 0" rpy="0 0 0" />
		   <geometry>
			<box size="0.255 0.150 0.04"/>
		   </geometry>
		   <material name="blue">
		      <color rgba="0 0.5 1 1"/>
		   </material>
		</visual>
		<!-- Base Collision -->
		<collision>
		   <origin xyz="0 0 0" rpy="0 0 0" />
		   <geometry>
			<box size="0.255 0.150 0.04"/>
		   </geometry>
		</collision>
		<!-- Base Inertial Elements -->
		<inertial>
		   <mass value="0.5"/>
		   <inertia ixx="0.002776" ixy="0.0" ixz="0.0"
			    iyy="0.003647" iyz="0.0" izz="0.001004"/>
		</inertial>
	</link>

	<!-- Right Back Wheel -->
	<link name="right_back_wheel">
	 	<visual>
		   <origin xyz="0 0 0" rpy="1.570795 0 0" />
		   <geometry>
			<cylinder length="0.026" radius="0.0325" />
		   </geometry>
		   <material name="black">
		      <color rgba="0.05 0.05 0.05 1"/>
		   </material>
		</visual>
		<!-- Right Back Wheel Collision -->
		<collision>
		   <origin xyz="0 0 0" rpy="1.570795 0 0" />
		   <geometry>
			<cylinder length="0.026" radius="0.0325" />
		   </geometry>
		</collision>
		<!-- Right Back Wheel Inertial Elements -->
		<inertial>
		   <mass value="0.01"/>
		   <inertia ixx="0.000003204" ixy="0.0" ixz="0.0"
			    iyy="0.000003204" iyz="0.0" izz="0.00005281"/>
		</inertial>
	</link>

	<joint name="joint_right_back_wheel" type="continuous">
	   <parent link="base_link"/>
	   <child link="right_back_wheel"/>
	   <origin xyz="-0.07 -0.086 0" rpy="0 0 0" />
	   <axis xyz="0 1 0"/>
	</joint>

	<!-- Right Front Wheel -->
	<link name="right_front_wheel">
	 	<visual>
		   <origin xyz="0 0 0" rpy="1.570795 0 0" />
		   <geometry>
			<cylinder length="0.026" radius="0.0325" />
		   </geometry>
		   <material name="black">
		      <color rgba="0.05 0.05 0.05 1"/>
		   </material>
		</visual>
		<!-- Right Front Wheel Collision -->
		<collision>
		   <origin xyz="0 0 0" rpy="1.570795 0 0" />
		   <geometry>
			<cylinder length="0.026" radius="0.0325" />
		   </geometry>
		</collision>
		<!-- Right Front Wheel Inertial Elements -->
		<inertial>
		   <mass value="0.01"/>
		   <inertia ixx="0.000003204" ixy="0.0" ixz="0.0"
			    iyy="0.000003204" iyz="0.0" izz="0.00005281"/>
		</inertial>
	</link>

	<joint name="joint_right_front_wheel" type="continuous">
	   <parent link="base_link"/>
	   <child link="right_front_wheel"/>
	   <origin xyz="0.07 -0.086 0" rpy="0 0 0" />
	   <axis xyz="0 1 0"/>
	</joint>

	<!-- Left Back Wheel -->
	<link name="left_back_wheel">
	 	<visual>
		   <origin xyz="0 0 0" rpy="1.570795 0 0" />
		   <geometry>
			<cylinder length="0.026" radius="0.0325" />
		   </geometry>
		   <material name="black">
		      <color rgba="0.05 0.05 0.05 1"/>
		   </material>
		</visual>
		<!-- Left Back Wheel Collision -->
		<collision>
		   <origin xyz="0 0 0" rpy="1.570795 0 0" />
		   <geometry>
			<cylinder length="0.026" radius="0.0325" />
		   </geometry>
		</collision>
		<!-- Left Back Wheel Inertial Elements -->
		<inertial>
		   <mass value="0.01"/>
		   <inertia ixx="0.000003204" ixy="0.0" ixz="0.0"
			    iyy="0.000003204" iyz="0.0" izz="0.00005281"/>
		</inertial>
	</link>

	<joint name="joint_left_back_wheel" type="continuous">
	   <parent link="base_link"/>
	   <child link="left_back_wheel"/>
	   <origin xyz="-0.07 0.086 0" rpy="0 0 0" />
	   <axis xyz="0 1 0"/>
	</joint>

	<!-- Left Front Wheel -->
	<link name="left_front_wheel">
	 	<visual>
		   <origin xyz="0 0 0" rpy="1.570795 0 0" />
		   <geometry>
			<cylinder length="0.026" radius="0.0325" />
		   </geometry>
		   <material name="black">
		      <color rgba="0.05 0.05 0.05 1"/>
		   </material>
		</visual>
		<!-- Left Front Wheel Collision -->
		<collision>
		   <origin xyz="0 0 0" rpy="1.570795 0 0" />
		   <geometry>
			<cylinder length="0.026" radius="0.0325" />
		   </geometry>
		</collision>
		<!--Left Front Wheel Inertial Elements -->
		<inertial>
		   <mass value="0.01"/>
		   <inertia ixx="0.000003204" ixy="0.0" ixz="0.0"
			    iyy="0.000003204" iyz="0.0" izz="0.00005281"/>
		</inertial>
	</link>

	<joint name="joint_left_front_wheel" type="continuous">
	   <parent link="base_link"/>
	   <child link="left_front_wheel"/>
	   <origin xyz="0.07 0.086 0" rpy="0 0 0" />
	   <axis xyz="0 1 0"/>
	</joint>

	<!-- Gazebo references -->
	<gazebo reference="base_link">
	   <material>Gazebo/Blue</material>
	</gazebo>
	<gazebo reference="right_front_wheel">
	   <material>Gazebo/Black</material>
	</gazebo>
	<gazebo reference="right_back_wheel">
	   <material>Gazebo/Black</material>
	</gazebo>
	<gazebo reference="left_front_wheel">
	   <material>Gazebo/Black</material>
	</gazebo>
	<gazebo reference="left_back_wheel">
	   <material>Gazebo/Black</material>
	</gazebo>

	
</robot> 
